/**
 * Componente ErrorBoundary para manejo de errores
 */

import React, { Component, ErrorInfo, ReactNode } from 'react'
import { AlertTriangle, RefreshCw, Home } from 'lucide-react'

interface Props {
  children: ReactNode
  fallback?: ReactNode
}

interface State {
  hasError: boolean
  error?: Error
  errorInfo?: ErrorInfo
}

export class ErrorBoundary extends Component<Props, State> {
  constructor(props: Props) {
    super(props)
    this.state = { hasError: false }
  }

  static getDerivedStateFromError(error: Error): State {
    return { hasError: true, error }
  }

  componentDidCatch(error: Error, errorInfo: ErrorInfo) {
    console.error('ErrorBoundary caught an error:', error, errorInfo)
    this.setState({ error, errorInfo })
  }

  handleRetry = () => {
    this.setState({ hasError: false, error: undefined, errorInfo: undefined })
  }

  handleGoHome = () => {
    window.location.href = '/'
  }

  render() {
    if (this.state.hasError) {
      if (this.props.fallback) {
        return this.props.fallback
      }

      return (
        <div className="min-h-screen flex items-center justify-center bg-gray-50">
          <div className="max-w-md w-full bg-white rounded-2xl shadow-xl p-8 text-center">
            <div className="mb-6">
              <div className="mx-auto w-16 h-16 bg-red-100 rounded-full flex items-center justify-center mb-4">
                <AlertTriangle className="w-8 h-8 text-red-600" />
              </div>
              <h2 className="text-2xl font-bold text-gray-900 mb-2">
                Algo sali√≥ mal
              </h2>
              <p className="text-gray-600 mb-6">
                Ha ocurrido un error inesperado. Por favor, intenta de nuevo.
              </p>
            </div>

            <div className="space-y-3">
              <button
                onClick={this.handleRetry}
                className="w-full bg-blue-600 text-white py-3 px-4 rounded-lg font-medium hover:bg-blue-700 transition-colors flex items-center justify-center gap-2"
              >
                <RefreshCw className="w-4 h-4" />
                Intentar de nuevo
              </button>
              
              <button
                onClick={this.handleGoHome}
                className="w-full bg-gray-100 text-gray-700 py-3 px-4 rounded-lg font-medium hover:bg-gray-200 transition-colors flex items-center justify-center gap-2"
              >
                <Home className="w-4 h-4" />
                Ir al inicio
              </button>
            </div>

            {process.env.NODE_ENV === 'development' && this.state.error && (
              <details className="mt-6 text-left">
                <summary className="cursor-pointer text-sm text-gray-500 hover:text-gray-700">
                  Detalles del error (solo desarrollo)
                </summary>
                <div className="mt-2 p-4 bg-gray-100 rounded-lg text-xs font-mono text-gray-800 overflow-auto">
                  <div className="mb-2">
                    <strong>Error:</strong> {this.state.error.message}
                  </div>
                  {this.state.errorInfo && (
                    <div>
                      <strong>Stack:</strong>
                      <pre className="mt-1 whitespace-pre-wrap">
                        {this.state.errorInfo.componentStack}
                      </pre>
                    </div>
                  )}
                </div>
              </details>
            )}
          </div>
        </div>
      )
    }

    return this.props.children
  }
}

// Hook para usar ErrorBoundary en componentes funcionales
export const useErrorHandler = () => {
  const [error, setError] = React.useState<Error | null>(null)

  const handleError = React.useCallback((error: Error) => {
    console.error('Error caught by useErrorHandler:', error)
    setError(error)
  }, [])

  const clearError = React.useCallback(() => {
    setError(null)
  }, [])

  return { error, handleError, clearError }
}
